# How does Promise chaining work?

## **âœ… What is Promise Chaining?**
**Promise chaining** is a technique used to **execute multiple asynchronous operations in sequence**, where the output of one `.then()` method **feeds into the next**. It helps avoid **callback hell** and makes asynchronous code more readable.

---

## **âœ… Basic Syntax of Promise Chaining**
```javascript
new Promise((resolve, reject) => {
    resolve(10); // Initial value
})
.then(value => {
    console.log(value); // 10
    return value * 2;  // Pass 20 to next .then()
})
.then(value => {
    console.log(value); // 20
    return value + 5;   // Pass 25 to next .then()
})
.then(value => {
    console.log(value); // 25
});
```
ðŸ“Œ **Key Takeaways:**  
âœ” Each `.then()` receives the **resolved value** from the previous `.then()`.  
âœ” A **new promise** is implicitly returned.  
âœ” Errors can be caught using `.catch()`.  

---

## **âœ… Example: Chaining API Calls**
```javascript
fetch('https://jsonplaceholder.typicode.com/users/1')
  .then(response => response.json()) // Convert response to JSON
  .then(user => {
      console.log(user.name); 
      return fetch(`https://jsonplaceholder.typicode.com/posts?userId=${user.id}`);
  })
  .then(response => response.json()) // Convert response to JSON
  .then(posts => console.log(posts)) // Log posts
  .catch(error => console.error("Error:", error)); // Handle errors
```
ðŸ“Œ **How It Works:**  
âœ” Fetches user data.  
âœ” Uses the user ID to fetch their posts.  
âœ” Logs the posts.  
âœ” Handles errors with `.catch()`.  

---

## **âœ… Handling Errors in Promise Chains**
Errors in a **promise chain** automatically **skip the remaining `.then()` blocks** and go directly to the `.catch()` block.

```javascript
new Promise((resolve, reject) => {
    reject("Something went wrong!");
})
.then(value => console.log("Won't execute", value)) // Skipped
.catch(error => console.error("Error:", error)); // âœ… Catches error
```

ðŸ”¹ If an error occurs **mid-chain**, the `.catch()` handles it:
```javascript
new Promise((resolve) => {
    resolve(10);
})
.then(value => {
    throw new Error("Oops!"); // ðŸš¨ Error occurs here
})
.then(value => console.log("Skipped:", value)) // Skipped
.catch(error => console.error("Caught error:", error.message)); // âœ… Handles error
```

---

## **âœ… Returning a Promise in Chaining**
If a `.then()` returns a **promise**, the next `.then()` **waits for it to resolve** before executing.

```javascript
function asyncTask(value) {
    return new Promise(resolve => setTimeout(() => resolve(value * 2), 1000));
}

asyncTask(5)
  .then(result => {
      console.log(result); // 10 after 1s
      return asyncTask(result);
  })
  .then(result => console.log(result)); // 20 after another 1s
```
ðŸ“Œ **Key Takeaways:**  
âœ” The second `.then()` **waits** for `asyncTask(result)` to finish.  
âœ” No **callback nesting** is needed.  

---

## **ðŸš€ Summary**
| **Feature** | **Behavior** |
|------------|-------------|
| **Sequential Execution** | `.then()` executes in order |
| **Passing Data** | Each `.then()` receives the previous result |
| **Error Handling** | `.catch()` catches errors from any `.then()` |
| **Returning Promises** | If a `.then()` returns a promise, the chain **waits** |
